Workbook

Sheet ESTRUCTURA
A1: OBSERVATORIO INMOBILIARIO NACIONÁL
A2: MODELO PARA LA PRESENTACION DE DATOS ANTE EL OBSERVATORIO INMOBILIARIO NACIONAL
A3: Código | B3: Componente | C3: Capa Geografica | D3: Tabla
B4: DINAMICA INMOBILIARIA | C4: =+'CAPA GEOGRÁFICA'!$C$6 -> Predios | D4: =+TABLA!$C$6 -> Predios
D5: Fisico/Construcciones
D6: Fisico/Terrenos
D7: Juridico/Tradicion
D8: Ofertas
D9: Avaluos

Sheet CAPA GEOGRÁFICA
B2: ESTRUCTURA DE DATOS - CAPAS GEOGRÁFICAS
B4: Descripción Tema | C4: Predios
C5: Comprende los predios de interes que se encuetren dentro de las zonas de estudio del gestor catastral
B6: Feature Class: | C6: Predios
B7: Geometría: | C7: Poligono
B8: CAMPO | C8: TIPO DE DATO | D8: DESCRIPCIÓN | E8: DOMINIO | F8: OBLIGACIÓN/CONDICIÓN | G8: PAQUETE LADM-COL | H8: CLASE
B9: ID_PREDIO | C9: String | D9: Identificador unico del predio a cargo del observatorio | E9: N/A | F9: Obligatorio
B10: CODIGO_OBSERVATORIO | C10: String | D10: Codigo del Observatorio directamente proporcionado una vez que el usuario se haya registrado en la pagina oficial del observatorio Inmobiliario Nacional | E10: N/A | F10: Obligatorio
B11: DEPARTAMENTO | C11: String | D11: Departamento de Colombia donde se encuentra ubicado el Predio | E11: N/A | F11: Obligatorio | G11: Unidad Administrativa Basica | H11: Clase. LC_Predio
B12: MUNICIPIO | C12: String | D12: Municipio de Colombia donde se encuentra ubicado el Predio | E12: N/A | F12: Obligatorio | G12: Unidad Administrativa Basica | H12: Clase. LC_Predio
B13: NUPRE | C13: String | D13: Es un código único para identificar los inmuebles tanto en los sistemas de información catastral como registral. El NUPRE no implicará supresión de la numeración catastral ni registral asociada a la cédula catastral ni a la matrícula inmobiliaria actual. | E13: N/A | F13: Obligatorio | G13: Unidad Administrativa Basica | H13: Clase. LC_Predio
B14: NUMERO_PREDIAL_ANTIGUO | C14: String | D14: Anterior Código numérico de veinte (20) dígitos | E14: N/A | F14: Obligatorio | G14: Unidad Administrativa Basica | H14: Clase. LC_Predio
B15: NUMERO PREDIAL NUEVO | C15: String | D15: Nuevo Código numérico de treinta (30) dígitos | E15: N/A | F15: Obligatorio | G15: Unidad Administrativa Basica | H15: Clase. LC_Predio
B16: CODIGO_ORIP | C16: String | D16: Codigo circulo registral | E16: N/A | F16: Obligatorio | G16: Unidad Administrativa Basica | H16: Clase. LC_Predio
B17: MATRICULA_INMOBILIARIA | C17: String | D17: Numero de Matricula inmobiliaria | E17: N/A | F17: Obligatorio | G17: Unidad Administrativa Basica | H17: Clase. LC_Predio
B18: GESTOR_CATASTRAL | C18: String | D18: Nombre o codigo del gestor catastral que proporciona la información | E18: N/A | F18: Obligatorio
B19: OPERADOR_CATASTRAL | C19: String | D19: Nombre del operador catastral | E19: N/A | F19: Opcional
B20: ZONA | C20: Dominio | D20: Especificar si el predio es urbano o rural | E20: =+DOMINIOS!C2 -> Dom_ClaseSueloTipo | F20: Obligatorio
B21: NOMBRE_SECTOR | C21: String | D21: Código de identificación única del sector catastral. | E21: N/A | F21: Opcional | G21: Submodelo de Cartografia ctastral | H21: Clase. CC_Sector_Urbano
B22: NOMBRE_LOCALIDAD_COMUNA | C22: String | D22: Nombre de la localidad o comuna aprobada por el acuerdo municipal. | E22: N/A | F22: Opcional | G22: Submodelo de Cartografia ctastral | H22: Clase. CC_Localidad_Comun a
B23: NOMBRE_BARRIO | C23: String | D23: Nombre del barrio aprobado en el acuerdo municipal. | E23: N/A | F23: Obligatorio | G23: Submodelo de Cartografia ctastral | H23: Clase. CC_Barrio
B24: VEREDA_MANZANA | C24: String | D24: Nombre de la verada o numero de la manzana de ubicación del predio | E24: N/A | F24: Obligatorio | G24: Unidad Espacial | H24: Clase. LC_Terreno
B25: TIPO | C25: Dominio | D25: Indica el tipo predio para efectos catastrales. | E25: =+DOMINIOS!C24 -> Dom_Predio_Tipo | F25: Obligatorio | G25: Unidad Administrativa Basica | H25: Clase. LC_Predio
B26: CONDICION_PREDIO | C26: Dominio | D26: Especifiar que tipo de condicion tiene la propiedad dentro de los dominos | E26: =+DOMINIOS!C35 -> Dom_Condicion_Predio_Tipo | F26: Obligatorio | G26: Unidad Administrativa Basica | H26: Clase. LC_Predio
B27: COPROPIEDAD | C27: String | D27: Identificador del predio matriz bajo el régimen de propiedad horizontal. | E27: N/A | F27: Condicional | G27: Unidad Administrativa Basica | H27: LC_Predio_Copropiedad
B28: PREDIO | C28: String | D28: Identificador de la unidad predial | E28: N/A | F28: Condicional | G28: Unidad Administrativa Basica | H28: LC_Predio_Copropiedad
B29: COEFICIENTE | C29: Number | D29: Coeficiente de copropiedad de la unidad predial. | E29: N/A | F29: Condicional | G29: Unidad Administrativa Basica | H29: LC_Predio_Copropiedad
B30: NUMERO_EDIFICIO_O_TORRE | C30: Number | D30: Torreo o edificio donde se encuentra el inmueble en PH | E30: N/A | F30: Condicional
B31: NUMERO_PISO_EDIFICIO | C31: Number | D31: Numero de piso dentro de la torre o edificio donde esta ubicado el apartamento en ph | E31: N/A | F31: Condicional
B32: NUMERO_UNIDAD | C32: Number | D32: Numero de la unidad dentro de la torreo o edificio | E32: N/A | F32: Condicional
B33: NUMERO_TORRES | C33: Number | D33: Número total de torres en el PH o Condominio | E33: N/A | F33: Condicional | G33: Unidad Administrativa Basica | H33: LC_DatosPHCondominio
B34: TOTAL_PISOS_TORRES | C34: Number | D34: Total de pisos por torre en el PH o Condominio. | E34: N/A | F34: Condicional | G34: Insumos del Gestor Catastral | H34: Clase. GC_DatosTorrePH
B35: TOTAL_UNIDADES_PRIVADAS | C35: Number | D35: Total de unidades privadas en el PH o Condominio. | E35: N/A | F35: Condicional | G35: Unidad Administrativa Basica | H35: LC_DatosPHCondominio
B36: TOTAL_SOTANOS | C36: Number | D36: Total de sótanos en PH o Condominio | E36: N/A | F36: Condicional | G36: Insumos del Gestor Catastral | H36: Clase. GC_Datos_PH_Condo minio
B37: TOTAL_PARQUEADEROS | C37: Number | D37: Total de parqueaderos en PH o Condominio | E37: N/A | F37: Condicional
B38: AVALUO_CATASTRAL | C38: Number | D38: Valor catastral del predio, obtenido mediante investigación y análisis estadístico del mercado inmobiliario y la metodología de aplicación correspondiente | E38: N/A | F38: Opcional | G38: Unidad Administrativa Basica | H38: Clase. LC_Predio
B39: DESTINACION_ECONOMICA | C39: Dominio | D39: Es la clasificación para fines estadísticos que se da a cada inmueble en su conjunto–terreno, construcciones o edificaciones-, en el momento de la identificación predial de conformidad con la actividad predominante que en él se desarrolle. | E39: =+DOMINIOS!C75 -> Dom_Destinacion_Economica | F39: Obligatorio | G39: Unidad Administrativa Basica | H39: Clase. LC_DatosAdicionalesLevantamientoCatastral
B40: DIRECCION | C40: Dominio | D40: Dirección del predio. | E40: =+DOMINIOS!$C$107 -> Ext_Direccion | F40: Obligatorio | G40: Unidad Administrativa Basica | H40: Clase. LC_Predio

Sheet TABLA
B2: ESTRUCTURA DE DATOS -TABLAS
B4: Descripción Tema | C4: Predios
C5: Comprende los predios de interes que se encuetren dentro de las zonas de estudio del gestor catastral
B6: Tabla | C6: Predios
B7: CAMPO | C7: TIPO DE DATO | D7: DESCRIPCIÓN | E7: DOMINIO | F7: OBLIGACIÓN/CONDICIÓN | G7: PAQUETE LADM-COL | H7: CLASE
B8: ID_PREDIO | C8: String | D8: Identificador unico del predio a cargo del observatorio | E8: N/A | F8: Obligatorio
B9: CODIGO_OBSERVATORIO | C9: String | D9: Codigo del Observatorio directamente proporcionado una vez que el usuario se haya registrado en la pagina oficial del observatorio Inmobiliario Nacional | E9: N/A | F9: Obligatorio
B10: DEPARTAMENTO | C10: String | D10: Departamento de Colombia donde se encuentra ubicado el Predio | E10: N/A | F10: Obligatorio | G10: Unidad Administrativa Basica | H10: Clase. LC_Predio
B11: MUNICIPIO | C11: String | D11: Municipio de Colombia donde se encuentra ubicado el Predio | E11: N/A | F11: Obligatorio | G11: Unidad Administrativa Basica | H11: Clase. LC_Predio
B12: NUPRE | C12: String | D12: Es un código único para identificar los inmuebles tanto en los sistemas de información catastral como registral. El NUPRE no implicará supresión de la numeración catastral ni registral asociada a la cédula catastral ni a la matrícula inmobiliaria actual. | E12: N/A | F12: Obligatorio | G12: Unidad Administrativa Basica | H12: Clase. LC_Predio
B13: NUMERO_PREDIAL_ANTIGUO | C13: String | D13: Anterior Código numérico de veinte (20) dígitos | E13: N/A | F13: Obligatorio | G13: Unidad Administrativa Basica | H13: Clase. LC_Predio
B14: NUMERO PREDIAL NUEVO | C14: String | D14: Nuevo Código numérico de treinta (30) dígitos | E14: N/A | F14: Obligatorio | G14: Unidad Administrativa Basica | H14: Clase. LC_Predio
B15: CODIGO_ORIP | C15: String | D15: Codigo circulo registral | E15: N/A | F15: Obligatorio | G15: Unidad Administrativa Basica | H15: Clase. LC_Predio
B16: MATRICULA_INMOBILIARIA | C16: String | D16: Numero de Matricula inmobiliaria | E16: N/A | F16: Obligatorio | G16: Unidad Administrativa Basica | H16: Clase. LC_Predio
B17: GESTOR_CATASTRAL | C17: String | D17: Nombre o codigo del gestor catastral que proporciona la información | E17: N/A | F17: Obligatorio
B18: OPERADOR_CATASTRAL | C18: String | D18: Nombre del operador catastral | E18: N/A | F18: Opcional
B19: ZONA | C19: Dominio | D19: Especificar si el predio es urbano o rural | E19: =+DOMINIOS!C2 -> Dom_ClaseSueloTipo | F19: Obligatorio
B20: NOMBRE_SECTOR | C20: String | D20: Código de identificación única del sector catastral. | E20: N/A | F20: Opcional | G20: Submodelo de Cartografia ctastral | H20: Clase. CC_Sector_Urbano
B21: NOMBRE_LOCALIDAD_COMUNA | C21: String | D21: Nombre de la localidad o comuna aprobada por el acuerdo municipal. | E21: N/A | F21: Opcional | G21: Submodelo de Cartografia ctastral | H21: Clase. CC_Localidad_Comun a
B22: NOMBRE_BARRIO | C22: String | D22: Nombre del barrio aprobado en el acuerdo municipal. | E22: N/A | F22: Obligatorio | G22: Submodelo de Cartografia ctastral | H22: Clase. CC_Barrio
B23: VEREDA_MANZANA | C23: String | D23: Nombre de la verada o numero de la manzana de ubicación del predio | E23: N/A | F23: Obligatorio | G23: Unidad Espacial | H23: Clase. LC_Terreno
B24: TIPO | C24: Dominio | D24: Indica el tipo predio para efectos catastrales. | E24: =+DOMINIOS!C24 -> Dom_Predio_Tipo | F24: Obligatorio | G24: Unidad Administrativa Basica | H24: Clase. LC_Predio
B25: CONDICION_PREDIO | C25: Dominio | D25: Especifiar que tipo de condicion tiene la propiedad dentro de los dominos | E25: =+DOMINIOS!C35 -> Dom_Condicion_Predio_Tipo | F25: Obligatorio | G25: Unidad Administrativa Basica | H25: Clase. LC_Predio
B26: COPROPIEDAD | C26: String | D26: Identificador del predio matriz bajo el régimen de propiedad horizontal. | E26: N/A | F26: Condicional | G26: Unidad Administrativa Basica | H26: LC_Predio_Copropiedad
B27: PREDIO | C27: String | D27: Identificador de la unidad predia | E27: N/A | F27: Condicional | G27: Unidad Administrativa Basica | H27: LC_Predio_Copropiedad
B28: COEFICIENTE | C28: Number | D28: Coeficiente de copropiedad de la unidad predial. | E28: N/A | F28: Condicional | G28: Unidad Administrativa Basica | H28: LC_Predio_Copropiedad
B29: NUMERO_EDIFICIO_O_TORRE | C29: Number | D29: Torreo o edificio donde se encuentra el inmueble en PH | E29: N/A | F29: Condicional
B30: NUMERO_PISO_EDIFICIO | C30: Number | D30: Numero de piso dentro de la torre o edificio | E30: N/A | F30: Condicional
B31: NUMERO_UNIDAD | C31: Number | D31: Numero de la unidad dentro de la torreo o edificio | E31: N/A | F31: Condicional
B32: NUMERO_TORRES | C32: Number | D32: Número de torres en el PH o Condominio | E32: N/A | F32: Condicional | G32: Unidad Administrativa Basica | H32: LC_DatosPHCondominio
B33: TOTAL_PISOS_TORRES | C33: Number | D33: Total de pisos por torre en el PH o Condominio. | E33: N/A | F33: Condicional | G33: Insumos del Gestor Catastral | H33: Clase. GC_DatosTorrePH
B34: TOTAL_UNIDADES_PRIVADAS | C34: Number | D34: Total de unidades privadas en el PH o Condominio. | E34: N/A | F34: Condicional | G34: Unidad Administrativa Basica | H34: LC_DatosPHCondominio
B35: TOTAL_SOTANOS | C35: Number | D35: Total de sótanos en PH o Condominio | E35: N/A | F35: Condicional | G35: Insumos del Gestor Catastral | H35: Clase. GC_Datos_PH_Condo minio
B36: TOTAL_PARQUEADEROS | C36: Number | D36: Total de parqueaderos en PH o Condominio | E36: N/A | F36: Condicional
B37: AVALUO_CATASTRAL | C37: Number | D37: Valor catastral del predio, obtenido mediante investigación y análisis estadístico del mercado inmobiliario y la metodología de aplicación correspondiente | E37: N/A | F37: Opcional | G37: Unidad Administrativa Basica | H37: Clase. LC_Predio
B38: DESTINACION_ECONOMICA | C38: Dominio | D38: Es la clasificación para fines estadísticos que se da a cada inmueble en su conjunto–terreno, construcciones o edificaciones-, en el momento de la identificación predial de conformidad con la actividad predominante que en él se desarrolle. | E38: =+DOMINIOS!C75 -> Dom_Destinacion_Economica | F38: Obligatorio | G38: Unidad Administrativa Basica | H38: Clase. LC_DatosAdicionalesLevantamientoCatastral
B39: DIRECCION | C39: Dominio | D39: Dirección del predio. | E39: =+DOMINIOS!$C$107 -> Ext_Direccion | F39: Obligatorio | G39: Unidad Administrativa Basica | H39: Clase. LC_Predio
B42: Descripción Tema | C42: Fisico/Construcciones
C43: Comprende la informacion de las construcciones que estan relacionadas con la calse predios que se encuetren dentro de las zonas de estudio del gestor catastral
B44: Tabla | C44: Fisico/Construcciones
...

Sheet DOMINIOS
B2: Dominio: | C2: Dom_ClaseSueloTipo
B3: CÓDIGO | C3: NOMBRE | D3: DESCRIPCIÓN
B4: 0 | C4: Urbano | D4: Constituyen el suelo urbano, las áreas del territorio distrital o municipal destinadas a usos urbanos por el plan de ordenamiento, que cuenten con infraestructura vial y redes primarias de energía, acueducto y alcantarillado, posibilitándose su urbanización y edificación,
B5: 1 | C5: Rural | D5: Constituyen esta categoría los terrenos no aptos para el uso urbano, por razones de oportunidad, o por su destinación a usos agrícolas, ganaderos, forestales, de explotación de recursos naturales y
B6: 2 | C6: Expansion_Urbana | D6: Constituido por la porción del territorio municipal destinada a la expansión urbana, que se habilitará para el uso urbano durante la vigencia del plan de ordenamiento, según lo determinen los Programas de Ejecución.
B9: Dominio: | C9: Dom_CategoriaSueloTipo
B10: CÓDIGO | C10: NOMBRE | D10: DESCRIPCIÓN
B11: 0 | C11: Suburbano | D11: Constituyen esta categoría las áreas ubicadas dentro del suelo rural, en las que se mezclan los usos del suelo y las formas de vida del campo y la ciudad, diferentes a las clasificadas como áreas de expansión urbana, que pueden ser objeto de desarrollo con restricciones de uso, de intensidad y de densidad, garantizando el autoabastecimiento en servicios públicos domiciliarios,
B12: 1 | C12: Proteccion | D12: Constituido por las zonas y áreas de terrenos localizados dentro de cualquiera de las anteriores clases, que por sus características geográficas, paisajísticas o ambientales, o por formar parte de las zonas de utilidad pública para la ubicación de infraestructuras para la provisión de servicios públicos domiciliarios o de las áreas de amenazas y riesgo no mitigable para la localización de asentamientos humanos, tiene restringida la posibilidad de urbanizarse. (Articulo 35, Ley 388 de 1997)
B15: Dominio: | C15: Dom_AccesoTipo
B16: CÓDIGO | C16: NOMBRE | D16: DESCRIPCIÓN
B17: 0 | C17: Ascensor_a_Piso | D17: Existe acceso mediante un ascensor que da acceso directo al piso.
B18: 1 | C18: Ascensor_Entre_Pisos | D18: Existe acceso mediante un ascensor que da acceso al entrepiso. REVISAR DOCUMENTACIÓN
B19: 2 | C19: Ascensor_Privado | D19: Existe acceso mediante un ascensor que da acceso directo a un espacio privado.
B20: 3 | C20: Escaleras | D20: Existe acceso mediante escaleras.
B21: 4 | C21: Escaleras_Electricas | D21: Existe acceso mediante escaleras eléctricas.
B24: Dominio: | C24: Dom_Predio_Tipo
B25: CÓDIGO | C25: NOMBRE | D25: DESCRIPCIÓN
B26: 0 | C26: Baldio | D26: Es un bien inmueble de propiedad de la Nación y ubicado en zonas rurales.
B27: 1 | C27: Fiscal | D27: Los bienes de la Unión cuyo uso no pertenece generalmente a los habitantes, se llaman bienes de la Unión o bienes fiscales.
B28: 2 | C28: Patrimonial | D28: Son bienes patrimoniales los de titularidad de las administraciones públicas que no tengan el carácter de bienes de dominio público, es decir, que no estén destinados directamente al uso público o afectados a un servicio público. Si no consta la afectación de un bien se presume su carácter patrimonial.
B29: 3 | C29: Uso_Publico | D29: Son aquellos inmuebles de dominio público cuyo uso pertenece a todos los habitantes del territorio nacional, LC_PredioTipo destinados al uso o disfrute colectivo.
B30: 4 | C30: Privado | D30: Es aquel que ha salido del patrimonio del estado, cuenta con un propietario inscrito en el folio de matrícula y se considera propiedad privada en los términos del artículo 48 de la Ley 160 de 1993.
B31: 5 | C31: Territorio_Colectivo | D31: Son los predios adjudicados a comunidades pertenecientes a grupos étnicos en el marco del reconocimiento de los resguardos legalmente constituidos según el Decreto 2164 de 1995 o de las propiedades colectivas de comunidades negras conforme Ley 70 de 1993.
B32: 6 | C32: Vacante | D32: Son bienes inmuebles que se encuentran dentro de territorio respectivo a cargo de la Nación, sin dueño aparente o conocido.
B35: Dominio: | C35: Dom_Condicion_Predio_Tipo
B36: CÓDIGO | C36: NOMBRE | D36: DESCRIPCIÓN
B37: 0 | C37: NPH | D37: Predio no sometido al régimen de propiedad horizontal.
B38: 1 | C38: PH_Matriz | D38: Predio matriz del régimen de propiedad horizontal sobre el cual se segregan todas las unidades prediales.
B39: 2 | C39: PH_Unidad_Predial | D39: Apartamento, garaje, depósito o cualquier otro tipo de unidad predial dentro del PH que se encuentra debidamente inscrito en el registro de instrumentos públicos
B40: 3 | C40: Condominio_Matriz | D40: Predio matriz del condominio sobre el cual se segregan todas las unidades prediales.
B41: 4 | C41: Condominio_Unidad_Predial | D41: Unidad predial dentro del condominio matriz
B42: 5 | C42: Mejora_PH | D42: Mejora sobre un predio sometido a régimen de propiedad horizontal
B43: 6 | C43: Mejora_NPH | D43: Mejora sobre un predio no sometido a régimen de propiedad horizontal.
B44: 7 | C44: Bien_Uso_Publico | D44: Inmuebles que siendo de dominio de la Nación, o una entidad territorial o de particulares, están destinados al uso de los habitantes.
B48: Dominio: | C48: Dom_Derecho_Tipo
B49: CÓDIGO | C49: NOMBRE | D49: DESCRIPCIÓN
B50: 0 | C50: Ocupacion | D50: En el ámbito de la gestión catastral, es el polígono que representa el asentamiento de personas naturales o jurídicas dentro de un terreno baldío, el cual puede contar o no con construcciones y/o edificaciones.
B51: 1 | C51: Posesión | D51: En el ámbito de la gestión catastral, es el polígono que representa el asentamiento de personas naturales o jurídicas, con ánimo de señor y dueño sobre un predio privado, el cual puede contar o no con construcciones y/o edificaciones
B52: 2 | C52: Derecho de Dominio o propiedad | D52: El dominio que se llama también propiedad es el derecho real en una cosa corporal, para gozar y disponer de ella arbitrariamente, no siendo contra ley o contra derecho ajeno.
...

Sheet ESPECIFICACIONES
B1: INSTRUCCIONES PARA DILIGENCIAR LOS FORMATOS DE ENTREGA DE DATOS AL OBSERVATORIO INMOBILIARIO NACIONAL
B2: OBSERVACIONES GENERALES
B3: El formato de entrega de datos al observatorio nacional debe ser diligenciado teniendo en cuenta el siguiente diccionario de datos en el cual se especifican cada una de las tablas o capas geograficas que deben ser entregadas por parte de los usuarios.
B4: Los Usuarios tienen dos opciones al momento de reportar la información al Observatorio Nacional y pueden escoger libremente cualquiera de las dos: OPCION 1: El usuario debe proporcionar la información en 5 tablas y una capa geográfica teniendo en cuenta la siguiente diferenciación: CAPA GEOGRAFICAS EN FORMATO GEOPACKAGE: Para esta estructura el usuario debe descargar la base de datos espacial en formato Geopackage proporcionada por el Observatorio inmobiliario Nacional en su sitio web y entregar las siguientes capas geográficas: • Capa Predios: En esta capa se almacena la estructura geográfica y la información espacial asociada a los predios. TABLAS DENTRO DEL GEOPACKAGE • Construcciones: En esta tabla se almacena la información alfanumérica asociada a las construcciones • Terrenos: En esta tabla se almacena la información alfanumérica asociada a los Terrenos. • Tradición: En esta tabla se almacena la información alfanumérica asociada a la tradición de los Predios. • Ofertas: En esta tabla se almacena la información alfanumérica asociada a las ofertas de venta o arrendamiento del sector estudiado por el observatorio. • Avalúos: En esta tabla se almacena la información alfanumérica asociada a los avalúos de los predios. OPCIÓN 2: Para esta opción el usuario debe suministrar la información de las 6 entidades en formato Excel(xlsm), teniendo en cuenta la estructura del diccionario de datos y el ejemplo de presentación de tablas para el observatorio nacional que puede ser descargado en la página web del observatorio TABLAS • Predios En esta tabla se almacena la información alfanumérica asociada a los predios. • Construcciones: En esta tabla se almacena la información alfanumérica asociada a las construcciones • Terrenos: En esta tabla se almacena la información alfanumérica asociada a los Terrenos. • Tradición: En esta tabla se almacena la información alfanumérica asociada a la tradición de los Predios. • Ofertas: En esta tabla se almacena la información alfanumérica asociada a las ofertas de venta o arrendamiento del sector estudiado por el observatorio. • Avalúos: En esta tabla se almacena la información alfanumérica asociada a los avalúos de los predios.
B5: En el diccionario de datos se debe tener en cuenta que algunos campos son obligatorios, otros son condicionales otros opcionales para saber en que momento diligenciar dicho campo favor seguir las siguientes especificaciones.
B6: Obligatorio | C6: El campo tiene que estar diligenciado obligatoriamente.
B7: Condicional | C7: El campo se debe diligenciar o no teniendo en cuenta si la información aplica para los siguientes casos: * Según la coherencia conceptual o lógica: - Cuando el diligenciamiento del campo depende de lo que se haya diligenciado en otro campo. - Por las relaciones entre una capa geográfica con otra capa geográfica o entre una capa geográfica y una tabla. Ejemplos: Campos especificos para los predios bajo el regimen de propiedad Horizontal PH
B8: Opcional | C8: El campo puede estar diligenciado o no.
